Workbook

Sheet Sheet1
B1: Yer2 | C1: Yer3 | D1: Yer4(09) | E1: Yer5
A2: 2021 | B2: 4 | C2: 4 | D2: 2 | E2: 2
A3: 2022 | B3: 2 | C3: 1 | D3: 2 | E3: 2
A4: 2023 | B4: 2 | C4: 1 | D4: 2 | E4: 4
A5: 2024 | B5: 1 | C5: 1 | D5: 2 | E5: 2
A6: 2025 | B6: 3 | C6: 2 | D6: 4 | E6: 3
A7: число | B7: класс
A8: 1 | B8: I
A9: 2 | B9: II
A10: 3 | B10: III
A11: 4 | B11: IV
A12: 5 | B12: V

Sheet Лист2
A1: 2021 | B1: Yer 2 | C1: Yer3 | D1: Yer4(09) | E1: Yer5
A2: =[1]Лист3!A2 -> Jan | B2: 1.4 | C2: 2.6 | D2: 2.4 | E2: 1.56
A3: =[1]Лист3!A3 -> Feb | B3: 0 | C3: 1 | D3: 1.55 | E3: 1.6
A4: =[1]Лист3!A4 -> Mart | B4: 0 | C4: 1 | D4: 1.55 | E4: 4.5
A5: =[1]Лист3!A5 -> April | B5: 0 | C5: 1.1 | D5: 2.43 | E5: 1.76
A6: =[1]Лист3!A6 -> May | B6: 3.1 | C6: 3.6 | D6: 1.5 | E6: 1.76
A7: =[1]Лист3!A7 -> June | B7: 0 | C7: 0 | D7: 1.46 | E7: 2.9
A8: =[1]Лист3!A8 -> July | B8: 1.6 | C8: 1.5 | D8: 2.95 | E8: 1.8
A9: =[1]Лист3!A9 -> August | B9: 1.6 | C9: 1.5 | D9: 1.93 | E9: 1.63
A10: =[1]Лист3!A10 -> Sept | B10: 1.8 | C10: 2.2 | D10: 3.2 | E10: 2
A11: =[1]Лист3!A11 -> Octob | B11: 0 | C11: 0 | D11: 1.7 | E11: 1
A12: =[1]Лист3!A12 -> Novem | B12: 1 | C12: 1 | D12: 1.5 | E12: 1.3
A13: =[1]Лист3!A13 -> Decem | B13: 0 | C13: 0 | D13: 1.93 | E13: 0

Sheet Лист1
A1: 2024 | B1: =Лист2!B1 -> Yer 2 | C1: =Лист2!C1 -> Yer3 | D1: =Лист2!D1 -> Yer4(09) | E1: =Лист2!E1 -> Yer5
A2: =Лист2!A2 -> Jan | B2: 3.6 | C2: 2.9 | D2: 5.3 | E2: 2.86
A3: =Лист2!A3 -> Feb | B3: 2.4 | C3: 2.8 | D3: 4.1 | E3: 1.8
A4: =Лист2!A4 -> Mart | B4: 2.4 | C4: 2.9 | D4: 2.66 | E4: 2.75
A5: =Лист2!A5 -> April | B5: 5 | C5: 3.4 | D5: 4.1 | E5: 3.53
A6: =Лист2!A6 -> May | B6: 1.3 | C6: 1.3 | D6: 2.6 | E6: 2.15
A7: =Лист2!A7 -> June | B7: 1.9 | C7: 2.6 | D7: 3.35 | E7: 3.15
A8: =Лист2!A8 -> July | B8: 1.1 | C8: 1.8 | D8: 1.9 | E8: 1.6
A9: =Лист2!A9 -> August | B9: 3.8 | C9: 1.9 | D9: 2.8 | E9: 3.8
A10: =Лист2!A10 -> Sept | B10: 1.4 | C10: 1.5 | D10: 1.85 | E10: 1.8
A11: =Лист2!A11 -> Octob | B11: 2.6 | C11: 3.7 | D11: 2.6 | E11: 1.76
A12: =Лист2!A12 -> Novem | B12: 2.1 | C12: 2.2 | D12: 2.13 | E12: 4.15
A13: =Лист2!A13 -> Decem | B13: 2.9 | C13: 3.1 | D13: 3.36 | E13: 2.93

Sheet Лист3
A1: 2022 | B1: Yer2 | C1: Yer3 | D1: Yer4(09) | E1: Yer5
A2: =Лист2!A2 -> Jan | B2: 0 | C2: 0 | D2: 1.8 | E2: 1.5
A3: =Лист2!A3 -> Feb | B3: 0 | C3: 0 | D3: 1.15 | E3: 1.1
A4: =Лист2!A4 -> Mart | B4: 0 | C4: 0 | D4: 1.26 | E4: 0
A5: =Лист2!A5 -> April | B5: 1 | C5: 1.1 | D5: 3.13 | E5: 3.36
A6: =Лист2!A6 -> May | B6: 1.4 | C6: 1.5 | D6: 2.4 | E6: 2.2
A7: =Лист2!A7 -> June | B7: 1.8 | C7: 1.6 | D7: 2.16 | E7: 1.8
A8: =Лист2!A8 -> July | B8: 1.3 | C8: 1.3 | D8: 1.43 | E8: 1.55
A9: =Лист2!A9 -> August | B9: 1.9 | C9: 2.1 | D9: 1.5 | E9: 2.2
A10: =Лист2!A10 -> Sept | B10: 1.9 | C10: 1.9 | D10: 1.6 | E10: 2
A11: =Лист2!A11 -> Octob | B11: 2 | C11: 2.1 | D11: 1.8 | E11: 1.5
A12: =Лист2!A12 -> Novem | B12: 1.4 | C12: 2 | D12: 2.05 | E12: 1.2
A13: =Лист2!A13 -> Decem | B13: 2.2 | C13: 1.7 | D13: 2.7 | E13: 1.85

Sheet Лист4
A1: 2023 | B1: =Лист3!B1 -> Yer2 | C1: =Лист3!C1 -> Yer3 | D1: =Лист3!D1 -> Yer4(09) | E1: =Лист3!E1 -> Yer5
A2: =Лист3!A2 -> Jan | B2: 1.5 | C2: 1.9 | D2: 1.86 | E2: 1.85
A3: =Лист3!A3 -> Feb | B3: 1.8 | C3: 2.15 | D3: 2.43 | E3: 1.7
A4: =Лист3!A4 -> Mart | B4: 2.1 | C4: 2.5 | D4: 3.58 | E4: 1.8
A5: =Лист3!A5 -> April | B5: 1 | C5: 1.1 | D5: 3.2 | E5: 4.65
A6: =Лист3!A6 -> May | B6: 0 | C6: 1.3 | D6: 2.56 | E6: 2.2
A7: =Лист3!A7 -> June | B7: 1.9 | C7: 1.8 | D7: 1.96 | E7: 2.05
A8: =Лист3!A8 -> July | B8: 2.2 | C8: 2 | D8: 2.06 | E8: 1.9
A9: =Лист3!A9 -> August | B9: 1.9 | C9: 1.8 | D9: 1.6 | E9: 1.6
A10: =Лист3!A10 -> Sept | B10: 1.5 | C10: 1.2 | D10: 2.8 | E10: 2
A11: =Лист3!A11 -> Octob | B11: 1.9 | C11: 3.1 | D11: 3.8 | E11: 3.7
A12: =Лист3!A12 -> Novem | B12: 2.5 | C12: 4.5 | D12: 4.9 | E12: 3.2
A13: =Лист3!A13 -> Decem | B13: 3.8 | C13: 1.35 | D13: 4.8 | E13: 2.66

Sheet Лист5
B1: =Лист4!B1 -> Yer2 | C1: =Лист4!C1 -> Yer3 | D1: =Лист4!D1 -> Yer4(09) | E1: =Лист4!E1 -> Yer5
A2: 2021 | B2: 0.88 | C2: 1.29 | D2: 2.01 | E2: 1.82
A3: 2022 | B3: 1.24 | C3: 1.27 | D3: 1.92 | E3: 1.68
A4: 2023 | B4: 1.84 | C4: 2.06 | D4: 2.96 | E4: 2.44
A5: 2024 | B5: 2.54 | C5: 2.51 | D5: 3.06 | E5: 2.69
A6: 2025 | B6: 1.48 | C6: 1.22 | D6: 2.51 | E6: 2.1

Sheet Лист6
A2: 2021 | B2: =Лист4!A2 -> Jan
A3: 2021 | B3: =Лист4!A3 -> Feb
A4: 2021 | B4: =Лист4!A4 -> Mart
A5: =A2 -> 2021 | B5: =Лист4!A5 -> April
A6: =A3 -> 2021 | B6: =Лист4!A6 -> May
A7: =A4 -> 2021 | B7: =Лист4!A7 -> June
A8: =A2 -> 2021 | B8: =Лист4!A8 -> July
A9: =A3 -> 2021 | B9: =Лист4!A9 -> August
A10: =A4 -> 2021 | B10: =Лист4!A10 -> Sept
A11: =A2 -> 2021 | B11: =Лист4!A11 -> Octob
A12: =A3 -> 2021 | B12: =Лист4!A12 -> Novem
A13: =A4 -> 2021 | B13: =Лист4!A13 -> Decem
A14: 2022 | B14: =B2 -> Jan
A15: 2022 | B15: =B3 -> Feb
A16: 2022 | B16: =B4 -> Mart
A17: 2022 | B17: =B5 -> April
A18: 2022 | B18: =B6 -> May
A19: 2022 | B19: =B7 -> June
A20: =A14 -> 2022 | B20: =B8 -> July
A21: =A15 -> 2022 | B21: =B9 -> August
A22: =A16 -> 2022 | B22: =B10 -> Sept
A23: =A17 -> 2022 | B23: =B11 -> Octob
A24: =A18 -> 2022 | B24: =B12 -> Novem
A25: =A19 -> 2022 | B25: =B13 -> Decem
A26: 2023 | B26: =B14 -> Jan
A27: 2023 | B27: =B15 -> Feb
A28: 2023 | B28: =B16 -> Mart
A29: 2023 | B29: =B17 -> April
A30: =A26 -> 2023 | B30: =B18 -> May
A31: =A27 -> 2023 | B31: =B19 -> June
A32: =A28 -> 2023 | B32: =B20 -> July
A33: =A29 -> 2023 | B33: =B21 -> August
A34: =A26 -> 2023 | B34: =B22 -> Sept
A35: =A27 -> 2023 | B35: =B23 -> Octob
A36: =A28 -> 2023 | B36: =B24 -> Novem
A37: =A29 -> 2023 | B37: =B25 -> Decem
A38: 2024 | B38: =B26 -> Jan
A39: 2024 | B39: =B27 -> Feb
A40: 2024 | B40: =B28 -> Mart
A41: 2024 | B41: =B29 -> April
...

Sheet Лист7
A1: СWPI | C1: T1 | D1: T2 | E1: T3 | F1: T4
A2: =Лист6!A2 -> 2021 | B2: =Лист6!B2 -> Jan | C2: =Лист2!B2 -> 1.4 | D2: =Лист2!C2 -> 2.6 | E2: =Лист2!D2 -> 2.4 | F2: =Лист2!E2 -> 1.56
A3: =Лист6!A3 -> 2021 | B3: =Лист6!B3 -> Feb | C3: =Лист2!B3 -> 0 | D3: =Лист2!C3 -> 1 | E3: =Лист2!D3 -> 1.55 | F3: =Лист2!E3 -> 1.6
A4: =Лист6!A4 -> 2021 | B4: =Лист6!B4 -> Mart | C4: =Лист2!B4 -> 0 | D4: =Лист2!C4 -> 1 | E4: =Лист2!D4 -> 1.55 | F4: =Лист2!E4 -> 4.5
A5: =Лист6!A5 -> 2021 | B5: =Лист6!B5 -> April | C5: =Лист2!B5 -> 0 | D5: =Лист2!C5 -> 1.1 | E5: =Лист2!D5 -> 2.43 | F5: =Лист2!E5 -> 1.76
A6: =Лист6!A6 -> 2021 | B6: =Лист6!B6 -> May | C6: =Лист2!B6 -> 3.1 | D6: =Лист2!C6 -> 3.6 | E6: =Лист2!D6 -> 1.5 | F6: =Лист2!E6 -> 1.76
A7: =Лист6!A7 -> 2021 | B7: =Лист6!B7 -> June | C7: =Лист2!B7 -> 0 | D7: =Лист2!C7 -> 0 | E7: =Лист2!D7 -> 1.46 | F7: =Лист2!E7 -> 2.9
A8: =Лист6!A8 -> 2021 | B8: =Лист6!B8 -> July | C8: =Лист2!B8 -> 1.6 | D8: =Лист2!C8 -> 1.5 | E8: =Лист2!D8 -> 2.95 | F8: =Лист2!E8 -> 1.8
A9: =Лист6!A9 -> 2021 | B9: =Лист6!B9 -> August | C9: =Лист2!B9 -> 1.6 | D9: =Лист2!C9 -> 1.5 | E9: =Лист2!D9 -> 1.93 | F9: =Лист2!E9 -> 1.63
A10: =Лист6!A10 -> 2021 | B10: =Лист6!B10 -> Sept | C10: =Лист2!B10 -> 1.8 | D10: =Лист2!C10 -> 2.2 | E10: =Лист2!D10 -> 3.2 | F10: =Лист2!E10 -> 2
A11: =Лист6!A11 -> 2021 | B11: =Лист6!B11 -> Octob | C11: =Лист2!B11 -> 0 | D11: =Лист2!C11 -> 0 | E11: =Лист2!D11 -> 1.7 | F11: =Лист2!E11 -> 1
A12: =Лист6!A12 -> 2021 | B12: =Лист6!B12 -> Novem | C12: =Лист2!B12 -> 1 | D12: =Лист2!C12 -> 1 | E12: =Лист2!D12 -> 1.5 | F12: =Лист2!E12 -> 1.3
A13: =Лист6!A13 -> 2021 | B13: =Лист6!B13 -> Decem | C13: =Лист2!B13 -> 0 | D13: =Лист2!C13 -> 0 | E13: =Лист2!D13 -> 1.93 | F13: =Лист2!E13 -> 0
A14: =Лист6!A14 -> 2022 | B14: =Лист6!B14 -> Jan | C14: =Лист3!B2 -> 0 | D14: =Лист3!C2 -> 0 | E14: =Лист3!D2 -> 1.8 | F14: =Лист3!E2 -> 1.5
A15: =Лист6!A15 -> 2022 | B15: =Лист6!B15 -> Feb | C15: =Лист3!B3 -> 0 | D15: =Лист3!C3 -> 0 | E15: =Лист3!D3 -> 1.15 | F15: =Лист3!E3 -> 1.1
A16: =Лист6!A16 -> 2022 | B16: =Лист6!B16 -> Mart | C16: =Лист3!B4 -> 0 | D16: =Лист3!C4 -> 0 | E16: =Лист3!D4 -> 1.26 | F16: =Лист3!E4 -> 0
A17: =Лист6!A17 -> 2022 | B17: =Лист6!B17 -> April | C17: =Лист3!B5 -> 1 | D17: =Лист3!C5 -> 1.1 | E17: =Лист3!D5 -> 3.13 | F17: =Лист3!E5 -> 3.36
A18: =Лист6!A18 -> 2022 | B18: =Лист6!B18 -> May | C18: =Лист3!B6 -> 1.4 | D18: =Лист3!C6 -> 1.5 | E18: =Лист3!D6 -> 2.4 | F18: =Лист3!E6 -> 2.2
A19: =Лист6!A19 -> 2022 | B19: =Лист6!B19 -> June | C19: =Лист3!B7 -> 1.8 | D19: =Лист3!C7 -> 1.6 | E19: =Лист3!D7 -> 2.16 | F19: =Лист3!E7 -> 1.8
A20: =Лист6!A20 -> 2022 | B20: =Лист6!B20 -> July | C20: =Лист3!B8 -> 1.3 | D20: =Лист3!C8 -> 1.3 | E20: =Лист3!D8 -> 1.43 | F20: =Лист3!E8 -> 1.55
A21: =Лист6!A21 -> 2022 | B21: =Лист6!B21 -> August | C21: =Лист3!B9 -> 1.9 | D21: =Лист3!C9 -> 2.1 | E21: =Лист3!D9 -> 1.5 | F21: =Лист3!E9 -> 2.2
A22: =Лист6!A22 -> 2022 | B22: =Лист6!B22 -> Sept | C22: =Лист3!B10 -> 1.9 | D22: =Лист3!C10 -> 1.9 | E22: =Лист3!D10 -> 1.6 | F22: =Лист3!E10 -> 2
A23: =Лист6!A23 -> 2022 | B23: =Лист6!B23 -> Octob | C23: =Лист3!B11 -> 2 | D23: =Лист3!C11 -> 2.1 | E23: =Лист3!D11 -> 1.8 | F23: =Лист3!E11 -> 1.5
A24: =Лист6!A24 -> 2022 | B24: =Лист6!B24 -> Novem | C24: =Лист3!B12 -> 1.4 | D24: =Лист3!C12 -> 2 | E24: =Лист3!D12 -> 2.05 | F24: =Лист3!E12 -> 1.2
A25: =Лист6!A25 -> 2022 | B25: =Лист6!B25 -> Decem | C25: =Лист3!B13 -> 2.2 | D25: =Лист3!C13 -> 1.7 | E25: =Лист3!D13 -> 2.7 | F25: =Лист3!E13 -> 1.85
A26: =Лист6!A26 -> 2023 | B26: =Лист6!B26 -> Jan | C26: =Лист4!B2 -> 1.5 | D26: =Лист4!C2 -> 1.9 | E26: =Лист4!D2 -> 1.86 | F26: =Лист4!E2 -> 1.85
A27: =Лист6!A27 -> 2023 | B27: =Лист6!B27 -> Feb | C27: =Лист4!B3 -> 1.8 | D27: =Лист4!C3 -> 2.15 | E27: =Лист4!D3 -> 2.43 | F27: =Лист4!E3 -> 1.7
A28: =Лист6!A28 -> 2023 | B28: =Лист6!B28 -> Mart | C28: =Лист4!B4 -> 2.1 | D28: =Лист4!C4 -> 2.5 | E28: =Лист4!D4 -> 3.58 | F28: =Лист4!E4 -> 1.8
A29: =Лист6!A29 -> 2023 | B29: =Лист6!B29 -> April | C29: =Лист4!B5 -> 1 | D29: =Лист4!C5 -> 1.1 | E29: =Лист4!D5 -> 3.2 | F29: =Лист4!E5 -> 4.65
A30: =Лист6!A30 -> 2023 | B30: =Лист6!B30 -> May | C30: =Лист4!B6 -> 0 | D30: =Лист4!C6 -> 1.3 | E30: =Лист4!D6 -> 2.56 | F30: =Лист4!E6 -> 2.2
A31: =Лист6!A31 -> 2023 | B31: =Лист6!B31 -> June | C31: =Лист4!B7 -> 1.9 | D31: =Лист4!C7 -> 1.8 | E31: =Лист4!D7 -> 1.96 | F31: =Лист4!E7 -> 2.05
A32: =Лист6!A32 -> 2023 | B32: =Лист6!B32 -> July | C32: =Лист4!B8 -> 2.2 | D32: =Лист4!C8 -> 2 | E32: =Лист4!D8 -> 2.06 | F32: =Лист4!E8 -> 1.9
A33: =Лист6!A33 -> 2023 | B33: =Лист6!B33 -> August | C33: =Лист4!B9 -> 1.9 | D33: =Лист4!C9 -> 1.8 | E33: =Лист4!D9 -> 1.6 | F33: =Лист4!E9 -> 1.6
A34: =Лист6!A34 -> 2023 | B34: =Лист6!B34 -> Sept | C34: =Лист4!B10 -> 1.5 | D34: =Лист4!C10 -> 1.2 | E34: =Лист4!D10 -> 2.8 | F34: =Лист4!E10 -> 2
A35: =Лист6!A35 -> 2023 | B35: =Лист6!B35 -> Octob | C35: =Лист4!B11 -> 1.9 | D35: =Лист4!C11 -> 3.1 | E35: =Лист4!D11 -> 3.8 | F35: =Лист4!E11 -> 3.7
A36: =Лист6!A36 -> 2023 | B36: =Лист6!B36 -> Novem | C36: =Лист4!B12 -> 2.5 | D36: =Лист4!C12 -> 4.5 | E36: =Лист4!D12 -> 4.9 | F36: =Лист4!E12 -> 3.2
A37: =Лист6!A37 -> 2023 | B37: =Лист6!B37 -> Decem | C37: =Лист4!B13 -> 3.8 | D37: =Лист4!C13 -> 1.35 | E37: =Лист4!D13 -> 4.8 | F37: =Лист4!E13 -> 2.66
A38: =Лист6!A38 -> 2024 | B38: =Лист6!B38 -> Jan | C38: =Лист1!B2 -> 3.6 | D38: =Лист1!C2 -> 2.9 | E38: =Лист1!D2 -> 5.3 | F38: =Лист1!E2 -> 2.86
A39: =Лист6!A39 -> 2024 | B39: =Лист6!B39 -> Feb | C39: =Лист1!B3 -> 2.4 | D39: =Лист1!C3 -> 2.8 | E39: =Лист1!D3 -> 4.1 | F39: =Лист1!E3 -> 1.8
A40: =Лист6!A40 -> 2024 | B40: =Лист6!B40 -> Mart | C40: =Лист1!B4 -> 2.4 | D40: =Лист1!C4 -> 2.9 | E40: =Лист1!D4 -> 2.66 | F40: =Лист1!E4 -> 2.75
...

Sheet Лист8
A1: 2025 | B1: =Лист2!B1 -> Yer 2 | C1: =Лист2!C1 -> Yer3 | D1: =Лист2!D1 -> Yer4(09) | E1: =Лист2!E1 -> Yer5
A2: =Лист2!A2 -> Jan | B2: =Лист7!C50 -> 1.4 | C2: =Лист7!D50 -> 2.1 | D2: =Лист7!E50 -> 1.86 | E2: =Лист7!F50 -> 1.36
A3: =Лист2!A3 -> Feb | B3: =Лист7!C51 -> 1.8 | C3: =Лист7!D51 -> 1.4 | D3: =Лист7!E51 -> 1.63 | E3: =Лист7!F51 -> 1.16
A4: =Лист2!A4 -> Mart | B4: =Лист7!C52 -> 0 | C4: =Лист7!D52 -> 1.5 | D4: =Лист7!E52 -> 1.7 | E4: =Лист7!F52 -> 1.4
A5: =Лист2!A5 -> April | B5: =Лист7!C53 -> 1.4 | C5: =Лист7!D53 -> 0 | D5: =Лист7!E53 -> 3.33 | E5: =Лист7!F53 -> 2.5
A6: =Лист2!A6 -> May | B6: =Лист7!C54 -> 2.9 | C6: =Лист7!D54 -> 2.4 | D6: =Лист7!E54 -> 2.26 | E6: =Лист7!F54 -> 2.3
A7: =Лист2!A7 -> June | B7: =Лист7!C55 -> 2.6 | C7: =Лист7!D55 -> 2.4 | D7: =Лист7!E55 -> 3.2 | E7: =Лист7!F55 -> 2.8
A8: =Лист2!A8 -> July | B8: =Лист7!C56 -> 1.3 | C8: =Лист7!D56 -> 0 | D8: =Лист7!E56 -> 2.5 | E8: =Лист7!F56 -> 2.45
A9: =Лист2!A9 -> August | B9: =Лист7!C57 -> 1.1 | C9: =Лист7!D57 -> 1 | D9: =Лист7!E57 -> 2.1 | E9: =Лист7!F57 -> 1.95
A10: =Лист2!A10 -> Sept | B10: =Лист7!C58 -> 1 | C10: =Лист7!D58 -> 0 | D10: =Лист7!E58 -> 2.1 | E10: =Лист7!F58 -> 2.45
A11: =Лист2!A11 -> Octob | B11: 1.4 | C11: 1 | D11: 2.6 | E11: 2.8
A12: =Лист2!A12 -> Novem | B12: 1.4 | C12: 1.6 | D12: 4.36 | E12: 1.9
A13: =Лист2!A13 -> Decem
